Workbook

Sheet 原始全量明细(发行前公告)
A1: 公告网页标题 | B1: 公告发布日期 | C1: 所属省份/计划单列市 | D1: 债券类型 | E1: 再融资子类(一般/专项) | F1: 发行期限 | G1: 批次(标题) | H1: 期数 | I1: 期数范围(合并行) | J1: 发行规模(亿元) | K1: 招投标日期(基准发行日) | L1: 基准日口径 | M1: 起息日 | N1: 上市流通日 | O1: 自然日间隔 | P1: 工作日间隔 | Q1: 发文号 | R1: 债券名称(PDF表格原文) | S1: 文件类型 | T1: 数据来源栏目 | U1: 提取方式(text/ocr/failed) | V1: 公告链接 | W1: 提取备注/警告
A2: 2018年江西省政府专项债券（十二期）信息披露文件 | B2: 43455 | C2: 江西省 | D2: 专项新增债券 | M2: 43462 | S2: announcement | T2: fxqgg | U2: ocr | V2: https://www.celma.org.cn/fxqgg/42599.jhtml | W2: 未能从表格解析分期明细，本行为整篇公告级别的合并记录; 未找到招标日期; 本行来自OCR识别，数值型字段准确性需人工核对
A3: 2018年黑龙江省政府一般债券（十一期）信息披露文件 | B3: 43455 | C3: 黑龙江省 | D3: 一般新增债券 | K3: 43462 | L3: 招标日 | M3: 43467 | O3: 7 | P3: 5 | S3: announcement | T3: fxqgg | U3: ocr | V3: https://www.celma.org.cn/fxqgg/42600.jhtml | W3: 未能从表格解析分期明细，本行为整篇公告级别的合并记录; 本行来自OCR识别，数值型字段准确性需人工核对
A4: 2018年浙江省（温州市、衢州市、台州市、丽水市）棚改专项债券（一期）--2018年浙江省政府专项债券（十二期） | B4: 43455 | C4: 浙江省 | D4: 专项新增债券 | J4: 22 | M4: 43462 | S4: announcement | T4: fxqgg | U4: ocr | V4: https://www.celma.org.cn/fxqgg/39652.jhtml | W4: 未能从表格解析分期明细，本行为整篇公告级别的合并记录; 未找到招标日期; 本行来自OCR识别，数值型字段准确性需人工核对
A5: 2018年江西省政府一般债券（十期）信息披露文件 | B5: 43455 | C5: 江西省 | D5: 一般新增债券 | M5: 43462 | S5: announcement | T5: fxqgg | U5: ocr | V5: https://www.celma.org.cn/fxqgg/44133.jhtml | W5: 未能从表格解析分期明细，本行为整篇公告级别的合并记录; 未找到招标日期; 本行来自OCR识别，数值型字段准确性需人工核对
A6: 2018年浙江省（绍兴市、衢州市）土地储备专项债券（一期）--2018年浙江省政府专项债券（十一期）信息披露文件 | B6: 43455 | C6: 浙江省 | D6: 专项新增债券 | J6: 18.6 | M6: 43462 | S6: announcement | T6: fxqgg | U6: ocr | V6: https://www.celma.org.cn/fxqgg/44061.jhtml | W6: 未能从表格解析分期明细，本行为整篇公告级别的合并记录; 未找到招标日期; 本行来自OCR识别，数值型字段准确性需人工核对
A7: 2018年新疆维吾尔自治区政府专项债券（十八期至十九期）招投标书 | B7: 43458 | C7: 新疆维吾尔自治区 | D7: 专项新增债券 | S7: announcement | T7: fxqgg | U7: text | V7: https://www.celma.org.cn/fxqgg/42595.jhtml | W7: 未能从表格解析分期明细，本行为整篇公告级别的合并记录; 未找到招标日期
A8: 2018年第四批青海省政府一般债券招投标书 | B8: 43458 | C8: 青海省 | D8: 一般新增债券 | G8: 4 | S8: announcement | T8: fxqgg | U8: ocr | V8: https://www.celma.org.cn/fxqgg/42594.jhtml | W8: 未能从表格解析分期明细，本行为整篇公告级别的合并记录; 未找到招标日期; 本行来自OCR识别，数值型字段准确性需人工核对
A9: 2018年第六批天津市政府专项债券信息披露文件 | B9: 43458 | C9: 天津市 | D9: 专项新增债券 | F9: 7Y | G9: 6 | H9: 2 | J9: 5 | K9: 43461 | L9: 招标日 | M9: 43462 | O9: 3 | P9: 3 | Q9: 津财库〔2018〕117 号 | R9: 2018年天津市宁河区生态保护专项债券（二期）‐2018年天津市政府专项债券（三十二期） | S9: announcement | T9: fxqgg | U9: text | V9: https://www.celma.org.cn/fxqgg/38671.jhtml
A10: 2018年第六批天津市政府专项债券信息披露文件 | B10: 43458 | C10: 天津市 | D10: 专项新增债券 | F10: 5Y | G10: 6 | H10: 3 | J10: 3 | K10: 43461 | L10: 招标日 | M10: 43462 | O10: 3 | P10: 3 | Q10: 津财库〔2018〕117 号 | R10: 2018年天津市滨海新区土地储备专项债券（三期）‐2018年天津市政府专项债券（三十四期） | S10: announcement | T10: fxqgg | U10: text | V10: https://www.celma.org.cn/fxqgg/38671.jhtml
A11: 2018年青岛市政府专项债券（十期）信息披露文件 | B11: 43459 | C11: 青岛市 | D11: 专项新增债券 | M11: 43462 | S11: announcement | T11: fxqgg | U11: ocr | V11: https://www.celma.org.cn/fxqgg/41570.jhtml | W11: 未能从表格解析分期明细，本行为整篇公告级别的合并记录; 未找到招标日期; 本行来自OCR识别，数值型字段准确性需人工核对
A12: 2018年山东省政府一般债券（九期）、专项债券（十一期）招投标文件 | B12: 43459 | C12: 山东省 | D12: 专项新增债券 | S12: announcement | T12: fxqgg | U12: ocr | V12: https://www.celma.org.cn/fxqgg/37746.jhtml | W12: 未能从表格解析分期明细，本行为整篇公告级别的合并记录; 未找到招标日期; 本行来自OCR识别，数值型字段准确性需人工核对
A13: 2018年青岛市政府一般债券（四期）信息披露文件 | B13: 43459 | C13: 青岛市 | D13: 一般新增债券 | M13: 43462 | S13: announcement | T13: fxqgg | U13: ocr | V13: https://www.celma.org.cn/fxqgg/37745.jhtml | W13: 未能从表格解析分期明细，本行为整篇公告级别的合并记录; 未找到招标日期; 本行来自OCR识别，数值型字段准确性需人工核对
A14: 2018年广西壮族自治区政府专项债券（十四期）招投标书 | B14: 43461 | C14: 广西壮族自治区 | D14: 专项新增债券 | Q14: 桂财库〔2018〕118 号 | S14: announcement | T14: fxqgg | U14: text | V14: https://www.celma.org.cn/fxqgg/41569.jhtml | W14: 未能从表格解析分期明细，本行为整篇公告级别的合并记录; 未找到招标日期
A15: 江西省地方政府债券招投标书（专项债券（十二期）） | B15: 43461 | C15: 江西省 | D15: 专项新增债券 | S15: announcement | T15: fxqgg | U15: ocr | V15: https://www.celma.org.cn/fxqgg/39648.jhtml | W15: 未能从表格解析分期明细，本行为整篇公告级别的合并记录; 未找到招标日期; 本行来自OCR识别，数值型字段准确性需人工核对
A16: 青岛市地方政府债券招投标书（18青岛13-14） | B16: 43461 | C16: 青岛市 | S16: announcement | T16: fxqgg | U16: ocr | V16: https://www.celma.org.cn/fxqgg/38668.jhtml | W16: 未能从表格解析分期明细，本行为整篇公告级别的合并记录; 标题含多品种或无法识别品种，请查看PDF人工拆分; 未找到招标日期; 本行来自OCR识别，数值型字段准确性需人工核对
A17: 2018年浙江省政府专项债券（十一-十二期）招投标书 | B17: 43461 | C17: 浙江省 | D17: 专项新增债券 | S17: announcement | T17: fxqgg | U17: ocr | V17: https://www.celma.org.cn/fxqgg/41568.jhtml | W17: 未能从表格解析分期明细，本行为整篇公告级别的合并记录; 未找到招标日期; 本行来自OCR识别，数值型字段准确性需人工核对
A18: 2018年广西壮族自治区政府一般债券（八期）招投标书 | B18: 43461 | C18: 广西壮族自治区 | D18: 一般新增债券 | Q18: 桂财库〔2018〕117 号 | S18: announcement | T18: fxqgg | U18: text | V18: https://www.celma.org.cn/fxqgg/39649.jhtml | W18: 未能从表格解析分期明细，本行为整篇公告级别的合并记录; 未找到招标日期
A19: 江西省地方政府债券招投标书（一般债券（十期）） | B19: 43461 | C19: 江西省 | D19: 一般新增债券 | S19: announcement | T19: fxqgg | U19: ocr | V19: https://www.celma.org.cn/fxqgg/38669.jhtml | W19: 未能从表格解析分期明细，本行为整篇公告级别的合并记录; 未找到招标日期; 本行来自OCR识别，数值型字段准确性需人工核对
A20: 2018年第六批天津市政府专项债券招投标书 | B20: 43461 | C20: 天津市 | D20: 专项新增债券 | G20: 6 | Q20: 津财库〔2018〕40 号 | S20: announcement | T20: fxqgg | U20: text | V20: https://www.celma.org.cn/fxqgg/44130.jhtml | W20: 未能从表格解析分期明细，本行为整篇公告级别的合并记录; 未找到招标日期
A21: 黑龙江省地方政府一般债券招投标书（18黑龙江债20） | B21: 43462 | C21: 黑龙江省 | D21: 一般新增债券 | S21: announcement | T21: fxqgg | U21: ocr | V21: https://www.celma.org.cn/fxqgg/44129.jhtml | W21: 未能从表格解析分期明细，本行为整篇公告级别的合并记录; 未找到招标日期; 本行来自OCR识别，数值型字段准确性需人工核对
A22: 黑龙江省地方政府专项债券招投标书（18黑龙江债21） | B22: 43462 | C22: 黑龙江省 | D22: 专项新增债券 | S22: announcement | T22: fxqgg | U22: ocr | V22: https://www.celma.org.cn/fxqgg/44058.jhtml | W22: 未能从表格解析分期明细，本行为整篇公告级别的合并记录; 未找到招标日期; 本行来自OCR识别，数值型字段准确性需人工核对
A23: 2019年新疆维吾尔自治区政府一般债券（一期）信息披露文件 | B23: 43479 | C23: 新疆维吾尔自治区 | D23: 一般新增债券 | K23: 43486 | L23: 招标日 | O23: 7 | P23: 5 | S23: announcement | T23: fxqgg | U23: text | V23: https://www.celma.org.cn/fxqgg/41649.jhtml | W23: 未能从表格解析分期明细，本行为整篇公告级别的合并记录
A24: 2019年河南省洛阳市城市轨道交通1号线专项债券信息披露文件 | B24: 43480 | C24: 河南省 | D24: 专项新增债券 | S24: announcement | T24: fxqgg | U24: text | V24: https://www.celma.org.cn/fxqgg/39647.jhtml | W24: 未能从表格解析分期明细，本行为整篇公告级别的合并记录; 未找到招标日期
A25: 2019年第一批河南省政府区域医疗专项债券信息披露文件 | B25: 43480 | C25: 河南省 | D25: 专项新增债券 | G25: 1 | S25: announcement | T25: fxqgg | U25: text | V25: https://www.celma.org.cn/fxqgg/41564.jhtml | W25: 未能从表格解析分期明细，本行为整篇公告级别的合并记录; 未找到招标日期
A26: 2019年河南省政府一般债券（一期）信息披露文件 | B26: 43480 | C26: 河南省 | D26: 一般新增债券 | M26: 43488 | S26: announcement | T26: fxqgg | U26: text | V26: https://www.celma.org.cn/fxqgg/38664.jhtml | W26: 未能从表格解析分期明细，本行为整篇公告级别的合并记录; 未找到招标日期
A27: 2019年第一批河南省政府土地储备专项债券信息披露文件 | B27: 43480 | C27: 河南省 | D27: 专项新增债券 | G27: 1 | S27: announcement | T27: fxqgg | U27: text | V27: https://www.celma.org.cn/fxqgg/41391.jhtml | W27: 未能从表格解析分期明细，本行为整篇公告级别的合并记录; 未找到招标日期
A28: 2019年第一批河南省政府棚户区改造专项债券信息披露文件 | B28: 43480 | C28: 河南省 | D28: 专项新增债券 | G28: 1 | S28: announcement | T28: fxqgg | U28: text | V28: https://www.celma.org.cn/fxqgg/44041.jhtml | W28: 未能从表格解析分期明细，本行为整篇公告级别的合并记录; 未找到招标日期
A29: 2019年新疆维吾尔自治区（新疆生产建设兵团）专项债券（一期）发行文件 | B29: 43481 | C29: 新疆维吾尔自治区 | D29: 专项新增债券 | J29: 2 | K29: 43488 | L29: 招标日 | M29: 43489 | O29: 7 | P29: 5 | S29: announcement | T29: fxqgg | U29: ocr | V29: https://www.celma.org.cn/fxqgg/43755.jhtml | W29: 未能从表格解析分期明细，本行为整篇公告级别的合并记录; 本行来自OCR识别，数值型字段准确性需人工核对
A30: 2019年新疆维吾尔自治区（新疆生产建设兵团）一般债券（一至二期）发行文件 | B30: 43481 | C30: 新疆维吾尔自治区 | D30: 一般新增债券 | J30: 11.2 | K30: 43488 | L30: 招标日 | M30: 43489 | O30: 7 | P30: 5 | S30: announcement | T30: fxqgg | U30: ocr | V30: https://www.celma.org.cn/fxqgg/40491.jhtml | W30: 未能从表格解析分期明细，本行为整篇公告级别的合并记录; 本行来自OCR识别，数值型字段准确性需人工核对
A31: 2019年新疆维吾尔自治区（新疆生产建设兵团）土地储备专项债券（一期）—2019年新疆维吾尔自治区（新疆生产建设兵团）专项债券（一期）发行文件 | B31: 43481 | C31: 新疆维吾尔自治区 | D31: 专项新增债券 | J31: 10 | K31: 43488 | L31: 招标日 | M31: 43489 | O31: 7 | P31: 5 | S31: announcement | T31: fxqgg | U31: ocr | V31: https://www.celma.org.cn/fxqgg/41388.jhtml | W31: 未能从表格解析分期明细，本行为整篇公告级别的合并记录; 本行来自OCR识别，数值型字段准确性需人工核对
A32: 2019年山东省政府一般债券一期信息披露文件 | B32: 43482 | C32: 山东省 | D32: 一般新增债券 | S32: announcement | T32: fxqgg | U32: ocr | V32: https://www.celma.org.cn/fxqgg/43622.jhtml | W32: 未能从表格解析分期明细，本行为整篇公告级别的合并记录; 未找到招标日期; 本行来自OCR识别，数值型字段准确性需人工核对
A33: 2019年山东省政府专项债券一期-四期信息披露文件 | B33: 43482 | C33: 山东省 | D33: 专项新增债券 | M33: 43490 | S33: announcement | T33: fxqgg | U33: ocr | V33: https://www.celma.org.cn/fxqgg/43692.jhtml | W33: 未能从表格解析分期明细，本行为整篇公告级别的合并记录; 未找到招标日期; 本行来自OCR识别，数值型字段准确性需人工核对
A34: 2019年第一批福建省政府一般债券发行信息披露文件 | B34: 43482 | C34: 福建省 | D34: 一般新增债券 | G34: 1 | M34: 43490 | S34: announcement | T34: fxqgg | U34: ocr | V34: https://www.celma.org.cn/fxqgg/43694.jhtml | W34: 未能从表格解析分期明细，本行为整篇公告级别的合并记录; 未找到招标日期; 本行来自OCR识别，数值型字段准确性需人工核对
A35: 2019年河北省本级收费公路专项债券信息披露文件 | B35: 43483 | C35: 河北省 | D35: 专项新增债券 | J35: 30 | K35: 43490 | L35: 招标日 | M35: 43493 | O35: 7 | P35: 5 | S35: announcement | T35: fxqgg | U35: ocr | V35: https://www.celma.org.cn/fxqgg/41400.jhtml | W35: 未能从表格解析分期明细，本行为整篇公告级别的合并记录; 本行来自OCR识别，数值型字段准确性需人工核对
A36: 2019年第一批天津市政府收费公路专项债券信息披露文件 | B36: 43483 | C36: 天津市 | D36: 专项新增债券 | F36: 15Y | G36: 1 | H36: 1 | J36: 4 | L36: 招标日 | M36: 43493 | Q36: 津财库〔2019〕7 号 | R36: 2019年天津市政府收费公路专项债券（一期）-2019年天津市政府专项债券（二期） | S36: announcement | T36: fxqgg | U36: text | V36: https://www.celma.org.cn/fxqgg/43636.jhtml | W36: 未找到招标日期
A37: 2019年第一批天津市政府城乡发展专项债券信息披露文件 | B37: 43483 | C37: 天津市 | D37: 专项新增债券 | F37: 10Y | G37: 1 | H37: 2 | J37: 10 | L37: 招标日 | M37: 43493 | Q37: 津财库〔2019〕7 号 | R37: 2019年天津市政府生态保护专项债券（二期）-2019年天津市政府专项债券（四期） | S37: announcement | T37: fxqgg | U37: text | V37: https://www.celma.org.cn/fxqgg/37518.jhtml | W37: 未找到招标日期
A38: 2019年第一批天津市政府一般债券信息披露文件 | B38: 43483 | C38: 天津市 | D38: 一般新增债券 | F38: 20Y | G38: 1 | H38: 3 | J38: 14 | L38: 招标日 | M38: 43493 | Q38: 津财库〔2019〕6 号 | R38: 2019年天津市政府一般债券（三期） | S38: announcement | T38: fxqgg | U38: text | V38: https://www.celma.org.cn/fxqgg/43268.jhtml | W38: 未找到招标日期
A39: 2019年第一批天津市政府城乡发展专项债券信息披露文件 | B39: 43483 | C39: 天津市 | D39: 专项新增债券 | F39: 3Y | G39: 1 | H39: 1 | J39: 5 | L39: 招标日 | M39: 43493 | Q39: 津财库〔2019〕7 号 | R39: 2019年天津市政府土地储备专项债券（一期）-2019年天津市政府专项债券（五期） | S39: announcement | T39: fxqgg | U39: text | V39: https://www.celma.org.cn/fxqgg/37518.jhtml | W39: 未找到招标日期
A40: 2019年第一批天津市政府城乡发展专项债券信息披露文件 | B40: 43483 | C40: 天津市 | D40: 专项新增债券 | F40: 5Y | G40: 1 | H40: 1 | J40: 27 | L40: 招标日 | M40: 43493 | Q40: 津财库〔2019〕7 号 | R40: 2019年天津市政府城乡发展专项债券（一期）-2019年天津市政府专项债券（七期） | S40: announcement | T40: fxqgg | U40: text | V40: https://www.celma.org.cn/fxqgg/37518.jhtml | W40: 未找到招标日期
...

Sheet 月度季度发行计划明细
A1: 公告网页标题 | B1: 计划公示日期 | C1: 所属省份/计划单列市 | D1: 覆盖年份 | E1: 覆盖起始月 | F1: 覆盖结束月 | G1: 覆盖期起始日 | H1: 覆盖期结束日 | I1: 计划新增一般债券规模(亿元) | J1: 计划新增专项债券规模(亿元) | K1: 计划再融资债券规模(亿元) | L1: 文件类型 | M1: 数据来源栏目 | N1: 提取方式(text/ocr/failed) | O1: 公告链接 | P1: 提取备注/警告
A2: 山东省（不含青岛）2019年2月政府债券发行计划表 | B2: 43483 | C2: 山东省 | D2: 2019 | E2: 2 | F2: 2 | G2: 43497 | H2: 43524 | L2: plan | M2: dfzfxjh | N2: ocr | O2: https://www.celma.org.cn/dfzfxjh/48535.jhtml | P2: 未找到再融资债券计划发行规模(表2-1); 未找到新增一般/专项债券计划发行规模(表2-2); 本行来自OCR识别，数值型字段准确性需人工核对
A3: 2019年3月山东省（不含青岛）政府债券发行工作安排 | B3: 43516 | C3: 山东省 | D3: 2019 | E3: 3 | F3: 3 | G3: 43525 | H3: 43555 | L3: plan | M3: dfzfxjh | N3: ocr | O3: https://www.celma.org.cn/dfzfxjh/48536.jhtml | P3: 未找到再融资债券计划发行规模(表2-1); 未找到新增一般/专项债券计划发行规模(表2-2); 本行来自OCR识别，数值型字段准确性需人工核对
A4: 2019年4月山东省（不含青岛）政府债券发行工作安排 | B4: 43544 | C4: 山东省 | D4: 2019 | E4: 4 | F4: 4 | G4: 43556 | H4: 43585 | L4: plan | M4: dfzfxjh | N4: ocr | O4: https://www.celma.org.cn/dfzfxjh/48537.jhtml | P4: 未找到再融资债券计划发行规模(表2-1); 未找到新增一般/专项债券计划发行规模(表2-2); 本行来自OCR识别，数值型字段准确性需人工核对
A5: 2019年5月山东省（不含青岛）政府债券发行工作安排 | B5: 43574 | C5: 山东省 | D5: 2019 | E5: 5 | F5: 5 | G5: 43586 | H5: 43616 | L5: plan | M5: dfzfxjh | N5: ocr | O5: https://www.celma.org.cn/dfzfxjh/48538.jhtml | P5: 未找到再融资债券计划发行规模(表2-1); 未找到新增一般/专项债券计划发行规模(表2-2); 本行来自OCR识别，数值型字段准确性需人工核对
A6: 2019年5月份河北省政府地方债券发行计划 | B6: 43577 | C6: 河北省 | D6: 2019 | E6: 5 | F6: 5 | G6: 43586 | H6: 43616 | L6: plan | M6: dfzfxjh | N6: ocr | O6: https://www.celma.org.cn/dfzfxjh/40993.jhtml | P6: 未找到再融资债券计划发行规模(表2-1); 未找到新增一般/专项债券计划发行规模(表2-2); 本行来自OCR识别，数值型字段准确性需人工核对
A7: 2019年二季度福建省政府发行计划表 | B7: 43599 | C7: 福建省 | D7: 2019 | E7: 4 | F7: 6 | G7: 43556 | H7: 43646 | L7: plan | M7: dfzfxjh | N7: ocr | O7: https://www.celma.org.cn/dfzfxjh/41018.jhtml | P7: 未找到再融资债券计划发行规模(表2-1); 未找到新增一般/专项债券计划发行规模(表2-2); 本行来自OCR识别，数值型字段准确性需人工核对
A8: 2019年6月山东省（不含青岛）政府债券发行工作安排 | B8: 43605 | C8: 山东省 | D8: 2019 | E8: 6 | F8: 6 | G8: 43617 | H8: 43646 | L8: plan | M8: dfzfxjh | N8: ocr | O8: https://www.celma.org.cn/dfzfxjh/48539.jhtml | P8: 未找到再融资债券计划发行规模(表2-1); 未找到新增一般/专项债券计划发行规模(表2-2); 本行来自OCR识别，数值型字段准确性需人工核对
A9: 2019年第二季度北京市地方政府新增债券和再融资债券发行计划表 | B9: 43615 | C9: 北京市 | D9: 2019 | E9: 4 | F9: 6 | G9: 43556 | H9: 43646 | L9: plan | M9: dfzfxjh | N9: ocr | O9: https://www.celma.org.cn/dfzfxjh/42978.jhtml | P9: 未找到再融资债券计划发行规模(表2-1); 未找到新增一般/专项债券计划发行规模(表2-2); 本行来自OCR识别，数值型字段准确性需人工核对
A10: 关于公布2019年三季度福建省政府债券发行计划及安排的通知 | B10: 43622 | C10: 福建省 | D10: 2019 | E10: 7 | F10: 9 | G10: 43647 | H10: 43738 | L10: plan | M10: dfzfxjh | N10: ocr | O10: https://www.celma.org.cn/dfzfxjh/39074.jhtml | P10: 未找到再融资债券计划发行规模(表2-1); 未找到新增一般/专项债券计划发行规模(表2-2); 本行来自OCR识别，数值型字段准确性需人工核对
A11: 关于公布2019年三季度厦门市地方政府债券发行计划的通知 | B11: 43634 | C11: 厦门市 | D11: 2019 | E11: 7 | F11: 9 | G11: 43647 | H11: 43738 | L11: plan | M11: dfzfxjh | N11: ocr | O11: https://www.celma.org.cn/dfzfxjh/42040.jhtml | P11: 未找到再融资债券计划发行规模(表2-1); 未找到新增一般/专项债券计划发行规模(表2-2); 本行来自OCR识别，数值型字段准确性需人工核对
A12: 关于公布2019年三季度浙江省地方政府债券发行计划的通知 | B12: 43634 | C12: 浙江省 | D12: 2019 | E12: 7 | F12: 9 | G12: 43647 | H12: 43738 | L12: plan | M12: dfzfxjh | N12: ocr | O12: https://www.celma.org.cn/dfzfxjh/42981.jhtml | P12: 未找到再融资债券计划发行规模(表2-1); 未找到新增一般/专项债券计划发行规模(表2-2); 本行来自OCR识别，数值型字段准确性需人工核对
A13: 关于公布2019年三季度青岛市地方政府债券发行计划的通知 | B13: 43635 | C13: 青岛市 | D13: 2019 | E13: 7 | F13: 9 | G13: 43647 | H13: 43738 | L13: plan | M13: dfzfxjh | N13: ocr | O13: https://www.celma.org.cn/dfzfxjh/42987.jhtml | P13: 未找到再融资债券计划发行规模(表2-1); 未找到新增一般/专项债券计划发行规模(表2-2); 本行来自OCR识别，数值型字段准确性需人工核对
... A26: 2019年6月甘肃省政府债券发行安排公告 | B26: 43777 | C26: 甘肃省 | D26: 2019 | E26: 6 | F26: 6 | G26: 43617 | H26: 43646 | L26: plan | M26: dfzfxjh | N26: ocr | O26: https://www.celma.org.cn/dfzfxjh/45879.jhtml | P26: 未找到再融资债券计划发行规模(表2-1); 未找到新增一般/专项债券计划发行规模(表2-2); 本行来自OCR识别，数值型字段准确性需人工核对
A27: 山西省2019年债券发行安排公开 | B27: 43784 | C27: 山西省 | I27: 258.442 | J27: 379 | K27: 119.53 | L27: plan | M27: dfzfxjh | N27: text | O27: https://www.celma.org.cn/dfzfxjh/46098.jhtml | P27: 未能从标题识别计划覆盖的月份/季度
A28: 2019年12月宁夏回族自治区债券发行安排公开 | B28: 43789 | C28: 宁夏回族自治区 | D28: 2019 | E28: 12 | F28: 12 | G28: 43800 | H28: 43830 | I28: 0 | J28: 0 | K28: 0 | L28: plan | M28: dfzfxjh | N28: text | O28: https://www.celma.org.cn/dfzfxjh/49526.jhtml
A29: 2019年云南省政府债券发行计划公开 | B29: 43794 | C29: 云南省 | L29: plan | M29: dfzfxjh | N29: text | O29: https://www.celma.org.cn/dfzfxjh/46152.jhtml | P29: 未能从标题识别计划覆盖的月份/季度
A30: 2020年01月贵州省债券发行安排公开 | B30: 43815 | C30: 贵州省 | D30: 2020 | E30: 1 | F30: 1 | G30: 43831 | H30: 43861 | I30: 0 | J30: 69.9 | K30: 0 | L30: plan | M30: dfzfxjh | N30: text | O30: https://www.celma.org.cn/dfzfxjh/50631.jhtml
A31: 2020年01月甘肃省债券发行安排公开 | B31: 43817 | C31: 甘肃省 | D31: 2020 | E31: 1 | F31: 1 | G31: 43831 | H31: 43861 | I31: 80.1 | J31: 123.22 | K31: 0 | L31: plan | M31: dfzfxjh | N31: text | O31: https://www.celma.org.cn/dfzfxjh/46793.jhtml
A32: 2020年01月吉林省债券发行安排公开 | B32: 43818 | C32: 吉林省 | D32: 2020 | E32: 1 | F32: 1 | G32: 43831 | H32: 43861 | I32: 0 | J32: 10.55 | K32: 0 | L32: plan | M32: dfzfxjh | N32: text | O32: https://www.celma.org.cn/dfzfxjh/47249.jhtml
A33: 2020年01月宁夏回族自治区债券发行安排公开 | B33: 43819 | C33: 宁夏回族自治区 | D33: 2020 | E33: 1 | F33: 1 | G33: 43831 | H33: 43861 | I33: 0 | J33: 0 | K33: 0 | L33: plan | M33: dfzfxjh | N33: text | O33: https://www.celma.org.cn/dfzfxjh/49520.jhtml
A34: 山东省（不含青岛）2020年1月政府债券发行计划表 | B34: 43819 | C34: 山东省 | D34: 2020 | E34: 1 | F34: 1 | G34: 43831 | H34: 43861 | L34: plan | M34: dfzfxjh | N34: ocr | O34: https://www.celma.org.cn/dfzfxjh/48534.jhtml | P34: 未找到再融资债券计划发行规模(表2-1); 未找到新增一般/专项债券计划发行规模(表2-2); 本行来自OCR识别，数值型字段准确性需人工核对
A35: 2020年1月甘肃省政府债券发行安排公告 | B35: 43830 | C35: 甘肃省 | D35: 2020 | E35: 1 | F35: 1 | G35: 43831 | H35: 43861 | L35: plan | M35: dfzfxjh | N35: ocr | O35: https://www.celma.org.cn/dfzfxjh/46862.jhtml | P35: 未找到再融资债券计划发行规模(表2-1); 未找到新增一般/专项债券计划发行规模(表2-2); 本行来自OCR识别，数值型字段准确性需人工核对
A36: 2020年01月河南省债券发行安排公开 | B36: 43832 | C36: 河南省 | D36: 2020 | E36: 1 | F36: 1 | G36: 43831 | H36: 43861 | I36: 0 | J36: 519 | K36: 0 | L36: plan | M36: dfzfxjh | N36: text | O36: https://www.celma.org.cn/dfzfxjh/46473.jhtml
A37: 2019年黑龙江省债券发行安排公开 | B37: 43833 | C37: 黑龙江省 | I37: 425.6 | J37: 263.89 | K37: 206.66 | L37: plan | M37: dfzfxjh | N37: text | O37: https://www.celma.org.cn/dfzfxjh/46496.jhtml | P37: 未能从标题识别计划覆盖的月份/季度
A38: 2020年02月贵州省债券发行安排公开 | B38: 43838 | C38: 贵州省 | D38: 2020 | E38: 2 | F38: 2 | G38: 43862 | H38: 43890 | I38: 0 | J38: 49.05 | K38: 0 | L38: plan | M38: dfzfxjh | N38: text | O38: https://www.celma.org.cn/dfzfxjh/50632.jhtml
A39: 2020年01月广西壮族自治区政府债券发行安排公开 | B39: 43839 | C39: 广西壮族自治区 | D39: 2020 | E39: 1 | F39: 1 | G39: 43831 | H39: 43861 | I39: 11 | J39: 105.41 | L39: plan | M39: dfzfxjh | N39: text | O39: https://www.celma.org.cn/dfzfxjh/46654.jhtml | P39: 未找到再融资债券计划发行规模(表2-1)
A40: 2020年1月广东省政府债券发行计划 | B40: 43840 | C40: 广东省 | D40: 2020 | E40: 1 | F40: 1 | G40: 43831 | H40: 43861 | L40: plan | M40: dfzfxjh | N40: ocr | O40: https://www.celma.org.cn/dfzfxjh/46799.jhtml | P40: 未找到再融资债券计划发行规模(表2-1); 未找到新增一般/专项债券计划发行规模(表2-2); 本行来自OCR识别，数值型字段准确性需人工核对
A41: 2020年02月宁夏回族自治区债券发行安排公开 | B41: 43850 | C41: 宁夏回族自治区 | D41: 2020 | E41: 2 | F41: 2 | G41: 43862 | H41: 43890 | I41: 0 | J41: 0 | K41: 0 | L41: plan | M41: dfzfxjh | N41: text | O41: https://www.celma.org.cn/dfzfxjh/49521.jhtml
A42: 山东省2020年2月份政府债券发行计划公开 | B42: 43850 | C42: 山东省 | D42: 2020 | E42: 2 | F42: 2 | G42: 43862 | H42: 43890 | L42: plan | M42: dfzfxjh | N42: ocr | O42: https://www.celma.org.cn/dfzfxjh/46730.jhtml | P42: 未找到再融资债券计划发行规模(表2-1); 未找到新增一般/专项债券计划发行规模(表2-2); 本行来自OCR识别，数值型字段准确性需人工核对
A43: 2020年青岛市债券发行安排公开 | B43: 43851 | C43: 青岛市 | I43: 0 | J43: 80 | K43: 0 | L43: plan | M43: dfzfxjh | N43: text | O43: https://www.celma.org.cn/dfzfxjh/46733.jhtml | P43: 未能从标题识别计划覆盖的月份/季度
A44: 2020年青岛市债券发行安排公开 | B44: 43852 | C44: 青岛市 | I44: 17.4 | J44: 80 | K44: 0 | L44: plan | M44: dfzfxjh | N44: text | O44: https://www.celma.org.cn/dfzfxjh/46758.jhtml | P44: 未能从标题识别计划覆盖的月份/季度
A45: 2020年02月青海省债券发行安排公开 | B45: 43852 | C45: 青海省 | D45: 2020 | E45: 2 | F45: 2 | G45: 43862 | H45: 43890 | I45: 152 | J45: 41 | K45: 0 | L45: plan | M45: dfzfxjh | N45: text | O45: https://www.celma.org.cn/dfzfxjh/46756.jhtml
A46: 2020年02月广西壮族自治区债券发行安排公开 | B46: 43852 | C46: 广西壮族自治区 | D46: 2020 | E46: 2 | F46: 2 | G46: 43862 | H46: 43890 | I46: 211 | J46: 289 | K46: 0 | L46: plan | M46: dfzfxjh | N46: text | O46: https://www.celma.org.cn/dfzfxjh/46760.jhtml
A47: 2020年01月云南省债券发行安排公开 | B47: 43853 | C47: 云南省 | D47: 2020 | E47: 1 | F47: 1 | G47: 43831 | H47: 43861 | I47: 141 | J47: 450 | K47: 0 | L47: plan | M47: dfzfxjh | N47: text | O47: https://www.celma.org.cn/dfzfxjh/46772.jhtml
A48: 2020年2月广东省政府债券发行计划 | B48: 43872 | C48: 广东省 | D48: 2020 | E48: 2 | F48: 2 | G48: 43862 | H48: 43890 | L48: plan | M48: dfzfxjh | N48: ocr | O48: https://www.celma.org.cn/dfzfxjh/46957.jhtml | P48: 未找到再融资债券计划发行规模(表2-1); 未找到新增一般/专项债券计划发行规模(表2-2); 本行来自OCR识别，数值型字段准确性需人工核对
A49: 2020年03月贵州省债券发行安排公开 | B49: 43873 | C49: 贵州省 | D49: 2020 | E49: 3 | F49: 3 | G49: 43891 | H49: 43921 | I49: 0 | J49: 31.05 | K49: 76 | L49: plan | M49: dfzfxjh | N49: text | O49: https://www.celma.org.cn/dfzfxjh/50633.jhtml
A50: 2020年03月吉林省债券发行安排公开 | B50: 43880 | C50: 吉林省 | D50: 2020 | E50: 3 | F50: 3 | G50: 43891 | H50: 43921 | I50: 187 | J50: 0 | K50: 72.58 | L50: plan | M50: dfzfxjh | N50: text | O50: https://www.celma.org.cn/dfzfxjh/47250.jhtml
A51: 2020年3月广东省政府债券发行计划 | B51: 43881 | C51: 广东省 | D51: 2020 | E51: 3 | F51: 3 | G51: 43891 | H51: 43921 | L51: plan | M51: dfzfxjh | N51: ocr | O51: https://www.celma.org.cn/dfzfxjh/47027.jhtml | P51: 未找到再融资债券计划发行规模(表2-1); 未找到新增一般/专项债券计划发行规模(表2-2); 本行来自OCR识别，数值型字段准确性需人工核对
A52: 山东省（不含青岛）2020年3月政府债券发行计划表 | B52: 43881 | C52: 山东省 | D52: 2020 | E52: 3 | F52: 3 | G52: 43891 | H52: 43921 | L52: plan | M52: dfzfxjh | N52: ocr | O52: https://www.celma.org.cn/dfzfxjh/46897.jhtml | P52: 未找到再融资债券计划发行规模(表2-1); 未找到新增一般/专项债券计划发行规模(表2-2); 本行来自OCR识别，数值型字段准确性需人工核对
...

Sheet 公式校验版
A1: 公告网页标题 | B1: 公告发布日期 | C1: 所属省份/计划单列市 | D1: 债券类型 | E1: 再融资子类(一般/专项) | F1: 发行期限 | G1: 批次(标题) | H1: 期数 | I1: 期数范围(合并行) | J1: 发行规模(亿元) | K1: 招投标日期(基准发行日) | L1: 基准日口径 | M1: 起息日 | N1: 上市流通日 | O1: 自然日间隔 | P1: 工作日间隔 | Q1: 发文号 | R1: 债券名称(PDF表格原文) | S1: 文件类型 | T1: 数据来源栏目 | U1: 提取方式(text/ocr/failed) | V1: 公告链接 | W1: 提取备注/警告
A2: 2018年江西省政府专项债券（十二期）信息披露文件 | B2: 43455 | C2: 江西省 | D2: 专项新增债券 | M2: 43462 | O2: =IF(OR(K2="",B2=""),"",K2-B2) | P2: =IF(OR(K2="",B2=""),"",NETWORKDAYS(B2+1,K2,法定节假日辅助表!$A$2:$A$142)+COUNTIFS(法定节假日辅助表!$B$2:$B$52,">="&(B2+1),法定节假日辅助表!$B$2:$B$52,"<="&K2)) | S2: announcement | T2: fxqgg | U2: ocr | V2: https://www.celma.org.cn/fxqgg/42599.jhtml | W2: 未能从表格解析分期明细，本行为整篇公告级别的合并记录; 未找到招标日期; 本行来自OCR识别，数值型字段准确性需人工核对
A3: 2018年黑龙江省政府一般债券（十一期）信息披露文件 | B3: 43455 | C3: 黑龙江省 | D3: 一般新增债券 | K3: 43462 | L3: 招标日 | M3: 43467 | O3: =IF(OR(K3="",B3=""),"",K3-B3) | P3: =IF(OR(K3="",B3=""),"",NETWORKDAYS(B3+1,K3,法定节假日辅助表!$A$2:$A$142)+COUNTIFS(法定节假日辅助表!$B$2:$B$52,">="&(B3+1),法定节假日辅助表!$B$2:$B$52,"<="&K3)) | S3: announcement | T3: fxqgg | U3: ocr | V3: https://www.celma.org.cn/fxqgg/42600.jhtml | W3: 未能从表格解析分期明细，本行为整篇公告级别的合并记录; 本行来自OCR识别，数值型字段准确性需人工核对
A4: 2018年浙江省（温州市、衢州市、台州市、丽水市）棚改专项债券（一期）--2018年浙江省政府专项债券（十二期） | B4: 43455 | C4: 浙江省 | D4: 专项新增债券 | J4: 22 | M4: 43462 | O4: =IF(OR(K4="",B4=""),"",K4-B4) | P4: =IF(OR(K4="",B4=""),"",NETWORKDAYS(B4+1,K4,法定节假日辅助表!$A$2:$A$142)+COUNTIFS(法定节假日辅助表!$B$2:$B$52,">="&(B4+1),法定节假日辅助表!$B$2:$B$52,"<="&K4)) | S4: announcement | T4: fxqgg | U4: ocr | V4: https://www.celma.org.cn/fxqgg/39652.jhtml | W4: 未能从表格解析分期明细，本行为整篇公告级别的合并记录; 未找到招标日期; 本行来自OCR识别，数值型字段准确性需人工核对
A5: 2018年江西省政府一般债券（十期）信息披露文件 | B5: 43455 | C5: 江西省 | D5: 一般新增债券 | M5: 43462 | O5: =IF(OR(K5="",B5=""),"",K5-B5) | P5: =IF(OR(K5="",B5=""),"",NETWORKDAYS(B5+1,K5,法定节假日辅助表!$A$2:$A$142)+COUNTIFS(法定节假日辅助表!$B$2:$B$52,">="&(B5+1),法定节假日辅助表!$B$2:$B$52,"<="&K5)) | S5: announcement | T5: fxqgg | U5: ocr | V5: https://www.celma.org.cn/fxqgg/44133.jhtml | W5: 未能从表格解析分期明细，本行为整篇公告级别的合并记录; 未找到招标日期; 本行来自OCR识别，数值型字段准确性需人工核对
A6: 2018年浙江省（绍兴市、衢州市）土地储备专项债券（一期）--2018年浙江省政府专项债券（十一期）信息披露文件 | B6: 43455 | C6: 浙江省 | D6: 专项新增债券 | J6: 18.6 | M6: 43462 | O6: =IF(OR(K6="",B6=""),"",K6-B6) | P6: =IF(OR(K6="",B6=""),"",NETWORKDAYS(B6+1,K6,法定节假日辅助表!$A$2:$A$142)+COUNTIFS(法定节假日辅助表!$B$2:$B$52,">="&(B6+1),法定节假日辅助表!$B$2:$B$52,"<="&K6)) | S6: announcement | T6: fxqgg | U6: ocr | V6: https://www.celma.org.cn/fxqgg/44061.jhtml | W6: 未能从表格解析分期明细，本行为整篇公告级别的合并记录; 未找到招标日期; 本行来自OCR识别，数值型字段准确性需人工核对
A7: 2018年新疆维吾尔自治区政府专项债券（十八期至十九期）招投标书 | B7: 43458 | C7: 新疆维吾尔自治区 | D7: 专项新增债券 | O7: =IF(OR(K7="",B7=""),"",K7-B7) | P7: =IF(OR(K7="",B7=""),"",NETWORKDAYS(B7+1,K7,法定节假日辅助表!$A$2:$A$142)+COUNTIFS(法定节假日辅助表!$B$2:$B$52,">="&(B7+1),法定节假日辅助表!$B$2:$B$52,"<="&K7)) | S7: announcement | T7: fxqgg | U7: text | V7: https://www.celma.org.cn/fxqgg/42595.jhtml | W7: 未能从表格解析分期明细，本行为整篇公告级别的合并记录; 未找到招标日期
A8: 2018年第四批青海省政府一般债券招投标书 | B8: 43458 | C8: 青海省 | D8: 一般新增债券 | G8: 4 | O8: =IF(OR(K8="",B8=""),"",K8-B8) | P8: =IF(OR(K8="",B8=""),"",NETWORKDAYS(B8+1,K8,法定节假日辅助表!$A$2:$A$142)+COUNTIFS(法定节假日辅助表!$B$2:$B$52,">="&(B8+1),法定节假日辅助表!$B$2:$B$52,"<="&K8)) | S8: announcement | T8: fxqgg | U8: ocr | V8: https://www.celma.org.cn/fxqgg/42594.jhtml | W8: 未能从表格解析分期明细，本行为整篇公告级别的合并记录; 未找到招标日期; 本行来自OCR识别，数值型字段准确性需人工核对
A9: 2018年第六批天津市政府专项债券信息披露文件 | B9: 43458 | C9: 天津市 | D9: 专项新增债券 | F9: 7Y | G9: 6 | H9: 2 | J9: 5 | K9: 43461 | L9: 招标日 | M9: 43462 | O9: =IF(OR(K9="",B9=""),"",K9-B9) | P9: =IF(OR(K9="",B9=""),"",NETWORKDAYS(B9+1,K9,法定节假日辅助表!$A$2:$A$142)+COUNTIFS(法定节假日辅助表!$B$2:$B$52,">="&(B9+1),法定节假日辅助表!$B$2:$B$52,"<="&K9)) | Q9: 津财库〔2018〕117 号 | R9: 2018年天津市宁河区生态保护专项债券（二期）‐2018年天津市政府专项债券（三十二期） | S9: announcement | T9: fxqgg | U9: text | V9: https://www.celma.org.cn/fxqgg/38671.jhtml
A10: 2018年第六批天津市政府专项债券信息披露文件 | B10: 43458 | C10: 天津市 | D10: 专项新增债券 | F10: 5Y | G10: 6 | H10: 3 | J10: 3 | K10: 43461 | L10: 招标日 | M10: 43462 | O10: =IF(OR(K10="",B10=""),"",K10-B10) | P10: =IF(OR(K10="",B10=""),"",NETWORKDAYS(B10+1,K10,法定节假日辅助表!$A$2:$A$142)+COUNTIFS(法定节假日辅助表!$B$2:$B$52,">="&(B10+1),法定节假日辅助表!$B$2:$B$52,"<="&K10)) | Q10: 津财库〔2018〕117 号 | R10: 2018年天津市滨海新区土地储备专项债券（三期）‐2018年天津市政府专项债券（三十四期） | S10: announcement | T10: fxqgg | U10: text | V10: https://www.celma.org.cn/fxqgg/38671.jhtml
A11: 2018年青岛市政府专项债券（十期）信息披露文件 | B11: 43459 | C11: 青岛市 | D11: 专项新增债券 | M11: 43462 | O11: =IF(OR(K11="",B11=""),"",K11-B11) | P11: =IF(OR(K11="",B11=""),"",NETWORKDAYS(B11+1,K11,法定节假日辅助表!$A$2:$A$142)+COUNTIFS(法定节假日辅助表!$B$2:$B$52,">="&(B11+1),法定节假日辅助表!$B$2:$B$52,"<="&K11)) | S11: announcement | T11: fxqgg | U11: ocr | V11: https://www.celma.org.cn/fxqgg/41570.jhtml | W11: 未能从表格解析分期明细，本行为整篇公告级别的合并记录; 未找到招标日期; 本行来自OCR识别，数值型字段准确性需人工核对
A12: 2018年山东省政府一般债券（九期）、专项债券（十一期）招投标文件 | B12: 43459 | C12: 山东省 | D12: 专项新增债券 | O12: =IF(OR(K12="",B12=""),"",K12-B12) | P12: =IF(OR(K12="",B12=""),"",NETWORKDAYS(B12+1,K12,法定节假日辅助表!$A$2:$A$142)+COUNTIFS(法定节假日辅助表!$B$2:$B$52,">="&(B12+1),法定节假日辅助表!$B$2:$B$52,"<="&K12)) | S12: announcement | T12: fxqgg | U12: ocr | V12: https://www.celma.org.cn/fxqgg/37746.jhtml | W12: 未能从表格解析分期明细，本行为整篇公告级别的合并记录; 未找到招标日期; 本行来自OCR识别，数值型字段准确性需人工核对
A13: 2018年青岛市政府一般债券（四期）信息披露文件 | B13: 43459 | C13: 青岛市 | D13: 一般新增债券 | M13: 43462 | O13: =IF(OR(K13="",B13=""),"",K13-B13) | P13: =IF(OR(K13="",B13=""),"",NETWORKDAYS(B13+1,K13,法定节假日辅助表!$A$2:$A$142)+COUNTIFS(法定节假日辅助表!$B$2:$B$52,">="&(B13+1),法定节假日辅助表!$B$2:$B$52,"<="&K13)) | S13: announcement | T13: fxqgg | U13: ocr | V13: https://www.celma.org.cn/fxqgg/37745.jhtml | W13: 未能从表格解析分期明细，本行为整篇公告级别的合并记录; 未找到招标日期; 本行来自OCR识别，数值型字段准确性需人工核对
A14: 2018年广西壮族自治区政府专项债券（十四期）招投标书 | B14: 43461 | C14: 广西壮族自治区 | D14: 专项新增债券 | O14: =IF(OR(K14="",B14=""),"",K14-B14) | P14: =IF(OR(K14="",B14=""),"",NETWORKDAYS(B14+1,K14,法定节假日辅助表!$A$2:$A$142)+COUNTIFS(法定节假日辅助表!$B$2:$B$52,">="&(B14+1),法定节假日辅助表!$B$2:$B$52,"<="&K14)) | Q14: 桂财库〔2018〕118 号 | S14: announcement | T14: fxqgg | U14: text | V14: https://www.celma.org.cn/fxqgg/41569.jhtml | W14: 未能从表格解析分期明细，本行为整篇公告级别的合并记录; 未找到招标日期
A15: 江西省地方政府债券招投标书（专项债券（十二期）） | B15: 43461 | C15: 江西省 | D15: 专项新增债券 | O15: =IF(OR(K15="",B15=""),"",K15-B15) | P15: =IF(OR(K15="",B15=""),"",NETWORKDAYS(B15+1,K15,法定节假日辅助表!$A$2:$A$142)+COUNTIFS(法定节假日辅助表!$B$2:$B$52,">="&(B15+1),法定节假日辅助表!$B$2:$B$52,"<="&K15)) | S15: announcement | T15: fxqgg | U15: ocr | V15: https://www.celma.org.cn/fxqgg/39648.jhtml | W15: 未能从表格解析分期明细，本行为整篇公告级别的合并记录; 未找到招标日期; 本行来自OCR识别，数值型字段准确性需人工核对
A16: 青岛市地方政府债券招投标书（18青岛13-14） | B16: 43461 | C16: 青岛市 | O16: =IF(OR(K16="",B16=""),"",K16-B16) | P16: =IF(OR(K16="",B16=""),"",NETWORKDAYS(B16+1,K16,法定节假日辅助表!$A$2:$A$142)+COUNTIFS(法定节假日辅助表!$B$2:$B$52,">="&(B16+1),法定节假日辅助表!$B$2:$B$52,"<="&K16)) | S16: announcement | T16: fxqgg | U16: ocr | V16: https://www.celma.org.cn/fxqgg/38668.jhtml | W16: 未能从表格解析分期明细，本行为整篇公告级别的合并记录; 标题含多品种或无法识别品种，请查看PDF人工拆分; 未找到招标日期; 本行来自OCR识别，数值型字段准确性需人工核对
A17: 2018年浙江省政府专项债券（十一-十二期）招投标书 | B17: 43461 | C17: 浙江省 | D17: 专项新增债券 | O17: =IF(OR(K17="",B17=""),"",K17-B17) | P17: =IF(OR(K17="",B17=""),"",NETWORKDAYS(B17+1,K17,法定节假日辅助表!$A$2:$A$142)+COUNTIFS(法定节假日辅助表!$B$2:$B$52,">="&(B17+1),法定节假日辅助表!$B$2:$B$52,"<="&K17)) | S17: announcement | T17: fxqgg | U17: ocr | V17: https://www.celma.org.cn/fxqgg/41568.jhtml | W17: 未能从表格解析分期明细，本行为整篇公告级别的合并记录; 未找到招标日期; 本行来自OCR识别，数值型字段准确性需人工核对
A18: 2018年广西壮族自治区政府一般债券（八期）招投标书 | B18: 43461 | C18: 广西壮族自治区 | D18: 一般新增债券 | O18: =IF(OR(K18="",B18=""),"",K18-B18) | P18: =IF(OR(K18="",B18=""),"",NETWORKDAYS(B18+1,K18,法定节假日辅助表!$A$2:$A$142)+COUNTIFS(法定节假日辅助表!$B$2:$B$52,">="&(B18+1),法定节假日辅助表!$B$2:$B$52,"<="&K18)) | Q18: 桂财库〔2018〕117 号 | S18: announcement | T18: fxqgg | U18: text | V18: https://www.celma.org.cn/fxqgg/39649.jhtml | W18: 未能从表格解析分期明细，本行为整篇公告级别的合并记录; 未找到招标日期
A19: 江西省地方政府债券招投标书（一般债券（十期）） | B19: 43461 | C19: 江西省 | D19: 一般新增债券 | O19: =IF(OR(K19="",B19=""),"",K19-B19) | P19: =IF(OR(K19="",B19=""),"",NETWORKDAYS(B19+1,K19,法定节假日辅助表!$A$2:$A$142)+COUNTIFS(法定节假日辅助表!$B$2:$B$52,">="&(B19+1),法定节假日辅助表!$B$2:$B$52,"<="&K19)) | S19: announcement | T19: fxqgg | U19: ocr | V19: https://www.celma.org.cn/fxqgg/38669.jhtml | W19: 未能从表格解析分期明细，本行为整篇公告级别的合并记录; 未找到招标日期; 本行来自OCR识别，数值型字段准确性需人工核对
A20: 2018年第六批天津市政府专项债券招投标书 | B20: 43461 | C20: 天津市 | D20: 专项新增债券 | G20: 6 | O20: =IF(OR(K20="",B20=""),"",K20-B20) | P20: =IF(OR(K20="",B20=""),"",NETWORKDAYS(B20+1,K20,法定节假日辅助表!$A$2:$A$142)+COUNTIFS(法定节假日辅助表!$B$2:$B$52,">="&(B20+1),法定节假日辅助表!$B$2:$B$52,"<="&K20)) | Q20: 津财库〔2018〕40 号 | S20: announcement | T20: fxqgg | U20: text | V20: https://www.celma.org.cn/fxqgg/44130.jhtml | W20: 未能从表格解析分期明细，本行为整篇公告级别的合并记录; 未找到招标日期
A21: 黑龙江省地方政府一般债券招投标书（18黑龙江债20） | B21: 43462 | C21: 黑龙江省 | D21: 一般新增债券 | O21: =IF(OR(K21="",B21=""),"",K21-B21) | P21: =IF(OR(K21="",B21=""),"",NETWORKDAYS(B21+1,K21,法定节假日辅助表!$A$2:$A$142)+COUNTIFS(法定节假日辅助表!$B$2:$B$52,">="&(B21+1),法定节假日辅助表!$B$2:$B$52,"<="&K21)) | S21: announcement | T21: fxqgg | U21: ocr | V21: https://www.celma.org.cn/fxqgg/44129.jhtml | W21: 未能从表格解析分期明细，本行为整篇公告级别的合并记录; 未找到招标日期; 本行来自OCR识别，数值型字段准确性需人工核对
A22: 黑龙江省地方政府专项债券招投标书（18黑龙江债21） | B22: 43462 | C22: 黑龙江省 | D22: 专项新增债券 | O22: =IF(OR(K22="",B22=""),"",K22-B22) | P22: =IF(OR(K22="",B22=""),"",NETWORKDAYS(B22+1,K22,法定节假日辅助表!$A$2:$A$142)+COUNTIFS(法定节假日辅助表!$B$2:$B$52,">="&(B22+1),法定节假日辅助表!$B$2:$B$52,"<="&K22)) | S22: announcement | T22: fxqgg | U22: ocr | V22: https://www.celma.org.cn/fxqgg/44058.jhtml | W22: 未能从表格解析分期明细，本行为整篇公告级别的合并记录; 未找到招标日期; 本行来自OCR识别，数值型字段准确性需人工核对
A23: 2019年新疆维吾尔自治区政府一般债券（一期）信息披露文件 | B23: 43479 | C23: 新疆维吾尔自治区 | D23: 一般新增债券 | K23: 43486 | L23: 招标日 | O23: =IF(OR(K23="",B23=""),"",K23-B23) | P23: =IF(OR(K23="",B23=""),"",NETWORKDAYS(B23+1,K23,法定节假日辅助表!$A$2:$A$142)+COUNTIFS(法定节假日辅助表!$B$2:$B$52,">="&(B23+1),法定节假日辅助表!$B$2:$B$52,"<="&K23)) | S23: announcement | T23: fxqgg | U23: text | V23: https://www.celma.org.cn/fxqgg/41649.jhtml | W23: 未能从表格解析分期明细，本行为整篇公告级别的合并记录
A24: 2019年河南省洛阳市城市轨道交通1号线专项债券信息披露文件 | B24: 43480 | C24: 河南省 | D24: 专项新增债券 | O24: =IF(OR(K24="",B24=""),"",K24-B24) | P24: =IF(OR(K24="",B24=""),"",NETWORKDAYS(B24+1,K24,法定节假日辅助表!$A$2:$A$142)+COUNTIFS(法定节假日辅助表!$B$2:$B$52,">="&(B24+1),法定节假日辅助表!$B$2:$B$52,"<="&K24)) | S24: announcement | T24: fxqgg | U24: text | V24: https://www.celma.org.cn/fxqgg/39647.jhtml | W24: 未能从表格解析分期明细，本行为整篇公告级别的合并记录; 未找到招标日期
A25: 2019年第一批河南省政府区域医疗专项债券信息披露文件 | B25: 43480 | C25: 河南省 | D25: 专项新增债券 | G25: 1 | O25: =IF(OR(K25="",B25=""),"",K25-B25) | P25: =IF(OR(K25="",B25=""),"",NETWORKDAYS(B25+1,K25,法定节假日辅助表!$A$2:$A$142)+COUNTIFS(法定节假日辅助表!$B$2:$B$52,">="&(B25+1),法定节假日辅助表!$B$2:$B$52,"<="&K25)) | S25: announcement | T25: fxqgg | U25: text | V25: https://www.celma.org.cn/fxqgg/41564.jhtml | W25: 未能从表格解析分期明细，本行为整篇公告级别的合并记录; 未找到招标日期
A26: 2019年河南省政府一般债券（一期）信息披露文件 | B26: 43480 | C26: 河南省 | D26: 一般新增债券 | M26: 43488 | O26: =IF(OR(K26="",B26=""),"",K26-B26) | P26: =IF(OR(K26="",B26=""),"",NETWORKDAYS(B26+1,K26,法定节假日辅助表!$A$2:$A$142)+COUNTIFS(法定节假日辅助表!$B$2:$B$52,">="&(B26+1),法定节假日辅助表!$B$2:$B$52,"<="&K26)) | S26: announcement | T26: fxqgg | U26: text | V26: https://www.celma.org.cn/fxqgg/38664.jhtml | W26: 未能从表格解析分期明细，本行为整篇公告级别的合并记录; 未找到招标日期
A27: 2019年第一批河南省政府土地储备专项债券信息披露文件 | B27: 43480 | C27: 河南省 | D27: 专项新增债券 | G27: 1 | O27: =IF(OR(K27="",B27=""),"",K27-B27) | P27: =IF(OR(K27="",B27=""),"",NETWORKDAYS(B27+1,K27,法定节假日辅助表!$A$2:$A$142)+COUNTIFS(法定节假日辅助表!$B$2:$B$52,">="&(B27+1),法定节假日辅助表!$B$2:$B$52,"<="&K27)) | S27: announcement | T27: fxqgg | U27: text | V27: https://www.celma.org.cn/fxqgg/41391.jhtml | W27: 未能从表格解析分期明细，本行为整篇公告级别的合并记录; 未找到招标日期
A28: 2019年第一批河南省政府棚户区改造专项债券信息披露文件 | B28: 43480 | C28: 河南省 | D28: 专项新增债券 | G28: 1 | O28: =IF(OR(K28="",B28=""),"",K28-B28) | P28: =IF(OR(K28="",B28=""),"",NETWORKDAYS(B28+1,K28,法定节假日辅助表!$A$2:$A$142)+COUNTIFS(法定节假日辅助表!$B$2:$B$52,">="&(B28+1),法定节假日辅助表!$B$2:$B$52,"<="&K28)) | S28: announcement | T28: fxqgg | U28: text | V28: https://www.celma.org.cn/fxqgg/44041.jhtml | W28: 未能从表格解析分期明细，本行为整篇公告级别的合并记录; 未找到招标日期
A29: 2019年新疆维吾尔自治区（新疆生产建设兵团）专项债券（一期）发行文件 | B29: 43481 | C29: 新疆维吾尔自治区 | D29: 专项新增债券 | J29: 2 | K29: 43488 | L29: 招标日 | M29: 43489 | O29: =IF(OR(K29="",B29=""),"",K29-B29) | P29: =IF(OR(K29="",B29=""),"",NETWORKDAYS(B29+1,K29,法定节假日辅助表!$A$2:$A$142)+COUNTIFS(法定节假日辅助表!$B$2:$B$52,">="&(B29+1),法定节假日辅助表!$B$2:$B$52,"<="&K29)) | S29: announcement | T29: fxqgg | U29: ocr | V29: https://www.celma.org.cn/fxqgg/43755.jhtml | W29: 未能从表格解析分期明细，本行为整篇公告级别的合并记录; 本行来自OCR识别，数值型字段准确性需人工核对
A30: 2019年新疆维吾尔自治区（新疆生产建设兵团）一般债券（一至二期）发行文件 | B30: 43481 | C30: 新疆维吾尔自治区 | D30: 一般新增债券 | J30: 11.2 | K30: 43488 | L30: 招标日 | M30: 43489 | O30: =IF(OR(K30="",B30=""),"",K30-B30) | P30: =IF(OR(K30="",B30=""),"",NETWORKDAYS(B30+1,K30,法定节假日辅助表!$A$2:$A$142)+COUNTIFS(法定节假日辅助表!$B$2:$B$52,">="&(B30+1),法定节假日辅助表!$B$2:$B$52,"<="&K30)) | S30: announcement | T30: fxqgg | U30: ocr | V30: https://www.celma.org.cn/fxqgg/40491.jhtml | W30: 未能从表格解析分期明细，本行为整篇公告级别的合并记录; 本行来自OCR识别，数值型字段准确性需人工核对
A31: 2019年新疆维吾尔自治区（新疆生产建设兵团）土地储备专项债券（一期）—2019年新疆维吾尔自治区（新疆生产建设兵团）专项债券（一期）发行文件 | B31: 43481 | C31: 新疆维吾尔自治区 | D31: 专项新增债券 | J31: 10 | K31: 43488 | L31: 招标日 | M31: 43489 | O31: =IF(OR(K31="",B31=""),"",K31-B31) | P31: =IF(OR(K31="",B31=""),"",NETWORKDAYS(B31+1,K31,法定节假日辅助表!$A$2:$A$142)+COUNTIFS(法定节假日辅助表!$B$2:$B$52,">="&(B31+1),法定节假日辅助表!$B$2:$B$52,"<="&K31)) | S31: announcement | T31: fxqgg | U31: ocr | V31: https://www.celma.org.cn/fxqgg/41388.jhtml | W31: 未能从表格解析分期明细，本行为整篇公告级别的合并记录; 本行来自OCR识别，数值型字段准确性需人工核对
A32: 2019年山东省政府一般债券一期信息披露文件 | B32: 43482 | C32: 山东省 | D32: 一般新增债券 | O32: =IF(OR(K32="",B32=""),"",K32-B32) | P32: =IF(OR(K32="",B32=""),"",NETWORKDAYS(B32+1,K32,法定节假日辅助表!$A$2:$A$142)+COUNTIFS(法定节假日辅助表!$B$2:$B$52,">="&(B32+1),法定节假日辅助表!$B$2:$B$52,"<="&K32)) | S32: announcement | T32: fxqgg | U32: ocr | V32: https://www.celma.org.cn/fxqgg/43622.jhtml | W32: 未能从表格解析分期明细，本行为整篇公告级别的合并记录; 未找到招标日期; 本行来自OCR识别，数值型字段准确性需人工核对
A33: 2019年山东省政府专项债券一期-四期信息披露文件 | B33: 43482 | C33: 山东省 | D33: 专项新增债券 | M33: 43490 | O33: =IF(OR(K33="",B33=""),"",K33-B33) | P33: =IF(OR(K33="",B33=""),"",NETWORKDAYS(B33+1,K33,法定节假日辅助表!$A$2:$A$142)+COUNTIFS(法定节假日辅助表!$B$2:$B$52,">="&(B33+1),法定节假日辅助表!$B$2:$B$52,"<="&K33)) | S33: announcement | T33: fxqgg | U33: ocr | V33: https://www.celma.org.cn/fxqgg/43692.jhtml | W33: 未能从表格解析分期明细，本行为整篇公告级别的合并记录; 未找到招标日期; 本行来自OCR识别，数值型字段准确性需人工核对
A34: 2019年第一批福建省政府一般债券发行信息披露文件 | B34: 43482 | C34: 福建省 | D34: 一般新增债券 | G34: 1 | M34: 43490 | O34: =IF(OR(K34="",B34=""),"",K34-B34) | P34: =IF(OR(K34="",B34=""),"",NETWORKDAYS(B34+1,K34,法定节假日辅助表!$A$2:$A$142)+COUNTIFS(法定节假日辅助表!$B$2:$B$52,">="&(B34+1),法定节假日辅助表!$B$2:$B$52,"<="&K34)) | S34: announcement | T34: fxqgg | U34: ocr | V34: https://www.celma.org.cn/fxqgg/43694.jhtml | W34: 未能从表格解析分期明细，本行为整篇公告级别的合并记录; 未找到招标日期; 本行来自OCR识别，数值型字段准确性需人工核对
A35: 2019年河北省本级收费公路专项债券信息披露文件 | B35: 43483 | C35: 河北省 | D35: 专项新增债券 | J35: 30 | K35: 43490 | L35: 招标日 | M35: 43493 | O35: =IF(OR(K35="",B35=""),"",K35-B35) | P35: =IF(OR(K35="",B35=""),"",NETWORKDAYS(B35+1,K35,法定节假日辅助表!$A$2:$A$142)+COUNTIFS(法定节假日辅助表!$B$2:$B$52,">="&(B35+1),法定节假日辅助表!$B$2:$B$52,"<="&K35)) | S35: announcement | T35: fxqgg | U35: ocr | V35: https://www.celma.org.cn/fxqgg/41400.jhtml | W35: 未能从表格解析分期明细，本行为整篇公告级别的合并记录; 本行来自OCR识别，数值型字段准确性需人工核对
A36: 2019年第一批天津市政府收费公路专项债券信息披露文件 | B36: 43483 | C36: 天津市 | D36: 专项新增债券 | F36: 15Y | G36: 1 | H36: 1 | J36: 4 | L36: 招标日 | M36: 43493 | O36: =IF(OR(K36="",B36=""),"",K36-B36) | P36: =IF(OR(K36="",B36=""),"",NETWORKDAYS(B36+1,K36,法定节假日辅助表!$A$2:$A$142)+COUNTIFS(法定节假日辅助表!$B$2:$B$52,">="&(B36+1),法定节假日辅助表!$B$2:$B$52,"<="&K36)) | Q36: 津财库〔2019〕7 号 | R36: 2019年天津市政府收费公路专项债券（一期）-2019年天津市政府专项债券（二期） | S36: announcement | T36: fxqgg | U36: text | V36: https://www.celma.org.cn/fxqgg/43636.jhtml | W36: 未找到招标日期
A37: 2019年第一批天津市政府城乡发展专项债券信息披露文件 | B37: 43483 | C37: 天津市 | D37: 专项新增债券 | F37: 10Y | G37: 1 | H37: 2 | J37: 10 | L37: 招标日 | M37: 43493 | O37: =IF(OR(K37="",B37=""),"",K37-B37) | P37: =IF(OR(K37="",B37=""),"",NETWORKDAYS(B37+1,K37,法定节假日辅助表!$A$2:$A$142)+COUNTIFS(法定节假日辅助表!$B$2:$B$52,">="&(B37+1),法定节假日辅助表!$B$2:$B$52,"<="&K37)) | Q37: 津财库〔2019〕7 号 | R37: 2019年天津市政府生态保护专项债券（二期）-2019年天津市政府专项债券（四期） | S37: announcement | T37: fxqgg | U37: text | V37: https://www.celma.org.cn/fxqgg/37518.jhtml | W37: 未找到招标日期
A38: 2019年第一批天津市政府一般债券信息披露文件 | B38: 43483 | C38: 天津市 | D38: 一般新增债券 | F38: 20Y | G38: 1 | H38: 3 | J38: 14 | L38: 招标日 | M38: 43493 | O38: =IF(OR(K38="",B38=""),"",K38-B38) | P38: =IF(OR(K38="",B38=""),"",NETWORKDAYS(B38+1,K38,法定节假日辅助表!$A$2:$A$142)+COUNTIFS(法定节假日辅助表!$B$2:$B$52,">="&(B38+1),法定节假日辅助表!$B$2:$B$52,"<="&K38)) | Q38: 津财库〔2019〕6 号 | R38: 2019年天津市政府一般债券（三期） | S38: announcement | T38: fxqgg | U38: text | V38: https://www.celma.org.cn/fxqgg/43268.jhtml | W38: 未找到招标日期
A39: 2019年第一批天津市政府城乡发展专项债券信息披露文件 | B39: 43483 | C39: 天津市 | D39: 专项新增债券 | F39: 3Y | G39: 1 | H39: 1 | J39: 5 | L39: 招标日 | M39: 43493 | O39: =IF(OR(K39="",B39=""),"",K39-B39) | P39: =IF(OR(K39="",B39=""),"",NETWORKDAYS(B39+1,K39,法定节假日辅助表!$A$2:$A$142)+COUNTIFS(法定节假日辅助表!$B$2:$B$52,">="&(B39+1),法定节假日辅助表!$B$2:$B$52,"<="&K39)) | Q39: 津财库〔2019〕7 号 | R39: 2019年天津市政府土地储备专项债券（一期）-2019年天津市政府专项债券（五期） | S39: announcement | T39: fxqgg | U39: text | V39: https://www.celma.org.cn/fxqgg/37518.jhtml | W39: 未找到招标日期
A40: 2019年第一批天津市政府城乡发展专项债券信息披露文件 | B40: 43483 | C40: 天津市 | D40: 专项新增债券 | F40: 5Y | G40: 1 | H40: 1 | J40: 27 | L40: 招标日 | M40: 43493 | O40: =IF(OR(K40="",B40=""),"",K40-B40) | P40: =IF(OR(K40="",B40=""),"",NETWORKDAYS(B40+1,K40,法定节假日辅助表!$A$2:$A$142)+COUNTIFS(法定节假日辅助表!$B$2:$B$52,">="&(B40+1),法定节假日辅助表!$B$2:$B$52,"<="&K40)) | Q40: 津财库〔2019〕7 号 | R40: 2019年天津市政府城乡发展专项债券（一期）-2019年天津市政府专项债券（七期） | S40: announcement | T40: fxqgg | U40: text | V40: https://www.celma.org.cn/fxqgg/37518.jhtml | W40: 未找到招标日期
...

Sheet 法定节假日辅助表
A1: 法定节假日(工作日调休为休息) | B1: 调休补班日(周末调整为工作日)
A2: 43465 | B2: 43463
A3: 43466 | B3: 43498
A4: 43500 | B4: 43499
A5: 43501 | B5: 43583
A6: 43502 | B6: 43590
A7: 43503 | B7: 43737
A8: 43504 | B8: 43750
A9: 43560 | B9: 43849
A10: 43586 | B10: 43947
A11: 43587 | B11: 43960
A12: 43588 | B12: 44010
A13: 43623 | B13: 44101
... A52: 44470 | B52: 46151
A53: 44473
A54: 44474
A55: 44475
A56: 44476
A57: 44564
A58: 44592
A59: 44593
A60: 44594
A61: 44595
A62: 44596
A63: 44655
A64: 44656
... A142: 46192
